Workbook
Name LABEL1: #REF!
Name NAME1: #REF!

Sheet Ops
B1: Jmp/Bra | C1: 1[4] | D1: 1[3:0] | F1: RegCmd | G1: 2[5:0] | I1: SelCtl1 | J1: 1[7:5] | L1: SelCtl2 | M1: 3[2:0] | O1: CtlSel3 | P1: 3[5:3] | R1: KeyMCntSel | S1: 1[3:0]
B2: JMP | C2: 1 | D2: 0000 | F2: CircX | G2: 000001 | I2: SelXReg | J2: 001 | L2: ClrXPh1 | M2: 001 | O2: SelQLQlsd | P2: 001 | R2: 0 | S2: 0000
A3: BR0 | B3: BRDecEven | C3: 1 | D3: 0000 | F3: DPAdjX | G3: 000001 | I3: LoadX9 | J3: 010 | L3: ClrYPh2 | M3: 010 | O3: SelYQYlsd | P3: 010 | R3: 1 | S3: 0001
A4: BR1 | B4: BRDigFull | C4: 1 | D4: 0001 | F4: EntNumX | G4: 000010 | I4: SelXQmsd | J4: 011 | L4: StatBitEn | M4: 011 | O4: StatBit1 | P4: 011 | R4: 2 | S4: 0010
A5: BR2 | B5: BRDigEmpty | C5: 1 | D5: 0010 | F5: LeftJustX | G5: 000010 | I5: LoadQL | J5: 100 | L5: SelXYlsd | M5: 100 | O5: SelX9Xmsd | P5: 100 | R5: 3 | S5: 0011
A6: BR3 | B6: BRDintOvrfl | C6: 1 | D6: 0011 | F6: DPAdjY | G6: 000100 | I6: SHDexpXDP | J6: 101 | L6: SelXSum | M6: 100 | O6: SelYXlsd | P6: 101 | R6: 4 | S6: 0100
A7: BR4 | B7: BRSignX | C7: 1 | D7: 0100 | F7: CopyXY | G7: 000101 | I7: Reserved1 | J7: 110 | L7: NxtPh | M7: 101 | O7: CntrIncr | P7: 110 | R7: 5 | S7: 0101
A8: BR5 | B8: BRSignY | C8: 1 | D8: 0101 | F8: ExchXY | G8: 000101 | I8: Reserved2 | J8: 111 | L8: CntrEn | M8: 110 | O8: RowHold | P8: 111 | R8: 6 | S8: 0110
A9: BR6 | B9: BRInOp2Ph | C9: 1 | D9: 0110 | F9: AddSub | G9: 000101 | I9: HWINTEN | J9: 000 | L9: SHSexpDexp | M9: 111 | O9: SelYZero | P9: 000 | R9: 7 | S9: 0111
A10: BR7 | B10: BRDPFree | C10: 1 | D10: 0111 | F10: DivXY10 | G10: 000101 | I10: SelXData | J10: 000 | L10: SelXX9 | M10: 000 | O10: SelQZero | P10: 000 | R10: 8 | S10: 1000
A11: BR8 | B11: BRQLZero | C11: 1 | D11: 1000 | F11: ShrX9X8QDiv10 | G11: 010001 | I11: SelXSumX9 | J11: 000 | L11: SelXXlsd | M11: 000 | O11: SelX9Zero | P11: 000 | R11: 9 | S11: 1001
A12: BR9 | B12: BRX9Zero | C12: 1 | D12: 1001 | F12: CopyYQ | G12: 010100 | I12: ExtraSelCtl1 | J12: 000 | L12: ExtraSelCtl1 | M12: 000 | O12: SelQLZero | P12: 000 | R12: BlankNum | S12: 1111
A13: BR10 | B13: BRDpOvrfl | C13: 1 | D13: 1010 | F13: CopyQX | G13: 100010 | I13: ExtraSelCtl2 | J13: 000 | L13: ExtraSelCtl2 | M13: 000 | O13: ExtraSelCtl3 | P13: 000 | R13: XDigCnt | S13: 0001
A14: BR11 | B14: BRNoKeyDet | C14: 1 | D14: 1011 | F14: ApendDivdn | G14: 000010 | I14: ExtraSelCtl3 | J14: 000 | R14: XDPCnt | S14: 0010
A15: BR12 | B15: BRIsNeg | C15: 1 | D15: 1100 | F15: RmLdZeroX | G15: 000010 | I15: ExtraSelCtl4 | J15: 000 | L15: ALUCmd | M15: 2[7:6] | O15: SEQ/DSKY | P15: 3[7:6] | R15: XYDexpCnt | S15: 0011
A16: BR13 | B16: BRCarryO | C16: 1 | D16: 1101 | F16: CopyQ0QL | G16: 100000 | L16: SubXY | M16: x1 | O16: HWINTEN | P16: 10 | R16: XYSexpCnt | S16: 0100
A17: BR14 | B17: BRSignXexp | C17: 1 | D17: 1110 | F17: ShrX | G17: 000001 | I17: BR* | J17: 001 | L17: CarryEn | M17: 1x | O17: KeyAck | P17: 01 | R17: X9Cnt | S17: 0101
A18: BR15 | B18: BRLoop8NZ | C18: 1 | D18: 1111 | F18: ShlX | G18: 000010 | O18: InitLP8 | P18: 01 | R18: QLCnt | S18: 0110
B19: BRSignYexp | C19: 1 | D19: 0110 | F19: CopyYX | G19: 000101 | R19: FixDP | S19: 0000
B20: BrNegExpTerm | C20: 1 | D20: 0101 | F20: ExtraCmd3 | G20: 000000 | R20: SignXexp | S20: 0001
B21: ExtraBR2 | C21: 0 | D21: 0000 | I21: ImmData asserts on Ph2 of each cycle | R21: NegExpTerm | S21: 0010
B22: ExtraBR3 | C22: 0 | D22: 0000 | I22: SelCtl1, SelCtl2, RegCmd, ALUCmd assert on Ph4 and is valid only Ph4 | R22: SignX | S22: 0011
B23: HWINTEN | C23: 0 | D23: 0000 | I23: SelCtl3, KeyAckB, HWIntEn Assert on Ph4 of each cycle | R23: SignY | S23: 0100
I24: SelCtl3 Can assert simutaneous with JMP/BR*. SelCtl1/2 cannot. | R24: SignYexp | S24: 0101
R25: AssertError | S25: 0110

Sheet ASM
A1: 7.5.3 | D1: I[5:0], I23 | F1: I[3:0] | G1: I[22] | H1: I[13:8] | I1: I[7:5] | J1: I[18:16] | K1: I[21:19] | L1: I[3:0] | M1: I[14] | N1: I[15] | O1: Logisim uROM Image | Z1: EEPROM Image
D2: 1[5:0], 3[7] | E2: 2[7:0], 3[2:0] | F2: 1[3:0] | G2: 3[6] | H2: 2[5:0] | I2: 1[7:5] | J2: 3[2:0] | K2: 3[5:3] | L2: 1[3:0] | M2: 2[6] | N2: 2[7] | O2: D[7:0] | P2: I[15:8] | Q2: I[23:16]
A3: Addr | B3: Hex | C3: Label | D3: SEQ | F3: DSKY | H3: REG | M3: AddSub | O3: 1[7:0] | P3: 2[7:0] | Q3: 3[7:0] | R3: 4 | Z3: {="#define ROMSZ "&INDEX(A5:A798,MATCH("ENDROM", C5:C798, 0),0)} -> #define ROMSZ 1983
D4: Bra | E4: Target | F4: Sel[3:0] | G4: KeyAck | H4: RegCmd | I4: SelCtl1 | J4: SelCtl2 | K4: SelCtl3 | L4: KeyMCntSel | M4: Sub_AddB | N4: CarryEn | O4: v2.0 raw | S4: Required for Logisim | Z4: ="const byte ROM[ROMSZ] PROGMEM= {" -> const byte ROM[ROMSZ] PROGMEM= {
A5: 0 | B5: =DEC2HEX(A5) -> 0 | O5: {=BIN2HEX(IF(I5<>"",VLOOKUP(I5,Ops!$I$2:'Ops'!$J$13,2,FALSE),IF(ISNUMBER(SEARCH("BR",D5)),"001","000"))&IF(D5<>"",VLOOKUP(D5,Ops!$B$2:'Ops'!$C$23,2,FALSE),"0")&_xlfn.IFS(ISNUMBER(SEARCH("BR",D5)),VLOOKUP(D5,Ops!$B$3:'Ops'!$D$22,3,FALSE),F5<>"",VLOOKUP(F5,Ops!$R$2:'Ops'!$S$11,2),L5<>"",VLOOKUP(L5,Ops!$R$2:'Ops'!$S$25,2,FALSE),TRUE,"0000"),2)} -> 00 | P5: =RIGHT(IF($E5<>"",_xlfn.XLOOKUP($E5,$C$4:$C$681,$B$4:$B$681,"NO LABEL"),BIN2HEX(IF(N5="CarryEn","1","0")&IF(M5="SubXY","1","0")&IF(H5<>"",VLOOKUP(H5,Ops!$F$2:'Ops'!$G$20,2,FALSE),"000000"),2)),2) -> 00 | Q5: {=BIN2HEX(_xlfn.IFS(D5="HWINTEN","10",G5="KeyAck","01",G5="InitLp8","01",TRUE,"00")&IF(OR(Ops!$O$2:'Ops'!$O$13=K5),VLOOKUP(K5,Ops!$O$2:'Ops'!$P$13,2,FALSE),"000")&IF(E5<>"",IF(LEN(_xlfn.XLOOKUP($E5,$C$5:$C$681,$B$5:$B$681,0))=3,HEX2BIN(LEFT(_xlfn.XLOOKUP($E5,$C$5:$C$681,$B$5:$B$681,0),1),3),IF(OR(Ops!$L$2:'Ops'!$L$11=J5),VLOOKUP(J5,Ops!$L$2:'Ops'!$M$11,2,FALSE),"000")),IF(OR(Ops!$L$2:'Ops'!$L$11=J5),VLOOKUP(J5,Ops!$L$2:'Ops'!$M$11,2,FALSE),"000")),2)} -> 00 | S5: Reset sequence | Z5: =IF(O5="", "};", "0x"&O5&",") -> 0x00, | AA5: ="0x"&P5&"," -> 0x00, | AB5: ="0x"&Q5&"," -> 0x00,
A6: =A5+3 -> 3 | B6: =DEC2HEX(A6) -> 3 | O6: {=BIN2HEX(IF(I6<>"",VLOOKUP(I6,Ops!$I$2:'Ops'!$J$13,2,FALSE),IF(ISNUMBER(SEARCH("BR",D6)),"001","000"))&IF(D6<>"",VLOOKUP(D6,Ops!$B$2:'Ops'!$C$23,2,FALSE),"0")&_xlfn.IFS(ISNUMBER(SEARCH("BR",D6)),VLOOKUP(D6,Ops!$B$3:'Ops'!$D$22,3,FALSE),F6<>"",VLOOKUP(F6,Ops!$R$2:'Ops'!$S$11,2),L6<>"",VLOOKUP(L6,Ops!$R$2:'Ops'!$S$25,2,FALSE),TRUE,"0000"),2)} -> 00 | P6: =RIGHT(IF($E6<>"",_xlfn.XLOOKUP($E6,$C$4:$C$681,$B$4:$B$681,"NO LABEL"),BIN2HEX(IF(N6="CarryEn","1","0")&IF(M6="SubXY","1","0")&IF(H6<>"",VLOOKUP(H6,Ops!$F$2:'Ops'!$G$20,2,FALSE),"000000"),2)),2) -> 00 | Q6: {=BIN2HEX(_xlfn.IFS(D6="HWINTEN","10",G6="KeyAck","01",G6="InitLp8","01",TRUE,"00")&IF(OR(Ops!$O$2:'Ops'!$O$13=K6),VLOOKUP(K6,Ops!$O$2:'Ops'!$P$13,2,FALSE),"000")&IF(E6<>"",IF(LEN(_xlfn.XLOOKUP($E6,$C$5:$C$681,$B$5:$B$681,0))=3,HEX2BIN(LEFT(_xlfn.XLOOKUP($E6,$C$5:$C$681,$B$5:$B$681,0),1),3),IF(OR(Ops!$L$2:'Ops'!$L$11=J6),VLOOKUP(J6,Ops!$L$2:'Ops'!$M$11,2,FALSE),"000")),IF(OR(Ops!$L$2:'Ops'!$L$11=J6),VLOOKUP(J6,Ops!$L$2:'Ops'!$M$11,2,FALSE),"000")),2)} -> 00 | Z6: =IF(O6="", "};", "0x"&O6&",") -> 0x00, | AA6: ="0x"&P6&"," -> 0x00, | AB6: ="0x"&Q6&"," -> 0x00,
A7: =A6+3 -> 6 | B7: =DEC2HEX(A7) -> 6 | C7: RESET | D7: JMP | E7: CLR | O7: {=BIN2HEX(IF(I7<>"",VLOOKUP(I7,Ops!$I$2:'Ops'!$J$13,2,FALSE),IF(ISNUMBER(SEARCH("BR",D7)),"001","000"))&IF(D7<>"",VLOOKUP(D7,Ops!$B$2:'Ops'!$C$23,2,FALSE),"0")&_xlfn.IFS(ISNUMBER(SEARCH("BR",D7)),VLOOKUP(D7,Ops!$B$3:'Ops'!$D$22,3,FALSE),F7<>"",VLOOKUP(F7,Ops!$R$2:'Ops'!$S$11,2),L7<>"",VLOOKUP(L7,Ops!$R$2:'Ops'!$S$25,2,FALSE),TRUE,"0000"),2)} -> 10 | P7: =RIGHT(IF($E7<>"",_xlfn.XLOOKUP($E7,$C$4:$C$681,$B$4:$B$681,"NO LABEL"),BIN2HEX(IF(N7="CarryEn","1","0")&IF(M7="SubXY","1","0")&IF(H7<>"",VLOOKUP(H7,Ops!$F$2:'Ops'!$G$20,2,FALSE),"000000"),2)),2) -> 2B | Q7: {=BIN2HEX(_xlfn.IFS(D7="HWINTEN","10",G7="KeyAck","01",G7="InitLp8","01",TRUE,"00")&IF(OR(Ops!$O$2:'Ops'!$O$13=K7),VLOOKUP(K7,Ops!$O$2:'Ops'!$P$13,2,FALSE),"000")&IF(E7<>"",IF(LEN(_xlfn.XLOOKUP($E7,$C$5:$C$681,$B$5:$B$681,0))=3,HEX2BIN(LEFT(_xlfn.XLOOKUP($E7,$C$5:$C$681,$B$5:$B$681,0),1),3),IF(OR(Ops!$L$2:'Ops'!$L$11=J7),VLOOKUP(J7,Ops!$L$2:'Ops'!$M$11,2,FALSE),"000")),IF(OR(Ops!$L$2:'Ops'!$L$11=J7),VLOOKUP(J7,Ops!$L$2:'Ops'!$M$11,2,FALSE),"000")),2)} -> 02 | Z7: =IF(O7="", "};", "0x"&O7&",") -> 0x10, | AA7: ="0x"&P7&"," -> 0x2B, | AB7: ="0x"&Q7&"," -> 0x02,
A8: =A7+3 -> 9 | B8: =DEC2HEX(A8) -> 9 | O8: {=BIN2HEX(IF(I8<>"",VLOOKUP(I8,Ops!$I$2:'Ops'!$J$13,2,FALSE),IF(ISNUMBER(SEARCH("BR",D8)),"001","000"))&IF(D8<>"",VLOOKUP(D8,Ops!$B$2:'Ops'!$C$23,2,FALSE),"0")&_xlfn.IFS(ISNUMBER(SEARCH("BR",D8)),VLOOKUP(D8,Ops!$B$3:'Ops'!$D$22,3,FALSE),F8<>"",VLOOKUP(F8,Ops!$R$2:'Ops'!$S$11,2),L8<>"",VLOOKUP(L8,Ops!$R$2:'Ops'!$S$25,2,FALSE),TRUE,"0000"),2)} -> 00 | P8: =RIGHT(IF($E8<>"",_xlfn.XLOOKUP($E8,$C$4:$C$681,$B$4:$B$681,"NO LABEL"),BIN2HEX(IF(N8="CarryEn","1","0")&IF(M8="SubXY","1","0")&IF(H8<>"",VLOOKUP(H8,Ops!$F$2:'Ops'!$G$20,2,FALSE),"000000"),2)),2) -> 00 | Q8: {=BIN2HEX(_xlfn.IFS(D8="HWINTEN","10",G8="KeyAck","01",G8="InitLp8","01",TRUE,"00")&IF(OR(Ops!$O$2:'Ops'!$O$13=K8),VLOOKUP(K8,Ops!$O$2:'Ops'!$P$13,2,FALSE),"000")&IF(E8<>"",IF(LEN(_xlfn.XLOOKUP($E8,$C$5:$C$681,$B$5:$B$681,0))=3,HEX2BIN(LEFT(_xlfn.XLOOKUP($E8,$C$5:$C$681,$B$5:$B$681,0),1),3),IF(OR(Ops!$L$2:'Ops'!$L$11=J8),VLOOKUP(J8,Ops!$L$2:'Ops'!$M$11,2,FALSE),"000")),IF(OR(Ops!$L$2:'Ops'!$L$11=J8),VLOOKUP(J8,Ops!$L$2:'Ops'!$M$11,2,FALSE),"000")),2)} -> 00 | S8: Null inst for table alignment | Z8: =IF(O8="", "};", "0x"&O8&",") -> 0x00, | AA8: ="0x"&P8&"," -> 0x00, | AB8: ="0x"&Q8&"," -> 0x00,
A9: =A8+3 -> 12 | B9: =DEC2HEX(A9) -> C | O9: {=BIN2HEX(IF(I9<>"",VLOOKUP(I9,Ops!$I$2:'Ops'!$J$13,2,FALSE),IF(ISNUMBER(SEARCH("BR",D9)),"001","000"))&IF(D9<>"",VLOOKUP(D9,Ops!$B$2:'Ops'!$C$23,2,FALSE),"0")&_xlfn.IFS(ISNUMBER(SEARCH("BR",D9)),VLOOKUP(D9,Ops!$B$3:'Ops'!$D$22,3,FALSE),F9<>"",VLOOKUP(F9,Ops!$R$2:'Ops'!$S$11,2),L9<>"",VLOOKUP(L9,Ops!$R$2:'Ops'!$S$25,2,FALSE),TRUE,"0000"),2)} -> 00 | P9: =RIGHT(IF($E9<>"",_xlfn.XLOOKUP($E9,$C$4:$C$681,$B$4:$B$681,"NO LABEL"),BIN2HEX(IF(N9="CarryEn","1","0")&IF(M9="SubXY","1","0")&IF(H9<>"",VLOOKUP(H9,Ops!$F$2:'Ops'!$G$20,2,FALSE),"000000"),2)),2) -> 00 | Q9: {=BIN2HEX(_xlfn.IFS(D9="HWINTEN","10",G9="KeyAck","01",G9="InitLp8","01",TRUE,"00")&IF(OR(Ops!$O$2:'Ops'!$O$13=K9),VLOOKUP(K9,Ops!$O$2:'Ops'!$P$13,2,FALSE),"000")&IF(E9<>"",IF(LEN(_xlfn.XLOOKUP($E9,$C$5:$C$681,$B$5:$B$681,0))=3,HEX2BIN(LEFT(_xlfn.XLOOKUP($E9,$C$5:$C$681,$B$5:$B$681,0),1),3),IF(OR(Ops!$L$2:'Ops'!$L$11=J9),VLOOKUP(J9,Ops!$L$2:'Ops'!$M$11,2,FALSE),"000")),IF(OR(Ops!$L$2:'Ops'!$L$11=J9),VLOOKUP(J9,Ops!$L$2:'Ops'!$M$11,2,FALSE),"000")),2)} -> 00 | R9: 00 | S9: Null inst for table alignment | Z9: =IF(O9="", "};", "0x"&O9&",") -> 0x00, | AA9: ="0x"&P9&"," -> 0x00, | AB9: ="0x"&Q9&"," -> 0x00, | AC9: 0x00,
A10: =A9+4 -> 16 | B10: =DEC2HEX(A10) -> 10 | D10: JMP | E10: ONE | G10: KeyAck | O10: {=BIN2HEX(IF(I10<>"",VLOOKUP(I10,Ops!$I$2:'Ops'!$J$13,2,FALSE),IF(ISNUMBER(SEARCH("BR",D10)),"001","000"))&IF(D10<>"",VLOOKUP(D10,Ops!$B$2:'Ops'!$C$23,2,FALSE),"0")&_xlfn.IFS(ISNUMBER(SEARCH("BR",D10)),VLOOKUP(D10,Ops!$B$3:'Ops'!$D$22,3,FALSE),F10<>"",VLOOKUP(F10,Ops!$R$2:'Ops'!$S$11,2),L10<>"",VLOOKUP(L10,Ops!$R$2:'Ops'!$S$25,2,FALSE),TRUE,"0000"),2)} -> 10 | P10: =RIGHT(IF($E10<>"",_xlfn.XLOOKUP($E10,$C$4:$C$681,$B$4:$B$681,"NO LABEL"),BIN2HEX(IF(N10="CarryEn","1","0")&IF(M10="SubXY","1","0")&IF(H10<>"",VLOOKUP(H10,Ops!$F$2:'Ops'!$G$20,2,FALSE),"000000"),2)),2) -> 7D | Q10: {=BIN2HEX(_xlfn.IFS(D10="HWINTEN","10",G10="KeyAck","01",G10="InitLp8","01",TRUE,"00")&IF(OR(Ops!$O$2:'Ops'!$O$13=K10),VLOOKUP(K10,Ops!$O$2:'Ops'!$P$13,2,FALSE),"000")&IF(E10<>"",IF(LEN(_xlfn.XLOOKUP($E10,$C$5:$C$681,$B$5:$B$681,0))=3,HEX2BIN(LEFT(_xlfn.XLOOKUP($E10,$C$5:$C$681,$B$5:$B$681,0),1),3),IF(OR(Ops!$L$2:'Ops'!$L$11=J10),VLOOKUP(J10,Ops!$L$2:'Ops'!$M$11,2,FALSE),"000")),IF(OR(Ops!$L$2:'Ops'!$L$11=J10),VLOOKUP(J10,Ops!$L$2:'Ops'!$M$11,2,FALSE),"000")),2)} -> 41 | R10: 00 | S10: Key stroke interrupt vector table | Z10: =IF(O10="", "};", "0x"&O10&",") -> 0x10, | AA10: ="0x"&P10&"," -> 0x7D, | AB10: ="0x"&Q10&"," -> 0x41, | AC10: 0x00,
A11: =A10+4 -> 20 | B11: =DEC2HEX(A11) -> 14 | D11: JMP | E11: FOUR | G11: KeyAck | O11: {=BIN2HEX(IF(I11<>"",VLOOKUP(I11,Ops!$I$2:'Ops'!$J$13,2,FALSE),IF(ISNUMBER(SEARCH("BR",D11)),"001","000"))&IF(D11<>"",VLOOKUP(D11,Ops!$B$2:'Ops'!$C$23,2,FALSE),"0")&_xlfn.IFS(ISNUMBER(SEARCH("BR",D11)),VLOOKUP(D11,Ops!$B$3:'Ops'!$D$22,3,FALSE),F11<>"",VLOOKUP(F11,Ops!$R$2:'Ops'!$S$11,2),L11<>"",VLOOKUP(L11,Ops!$R$2:'Ops'!$S$25,2,FALSE),TRUE,"0000"),2)} -> 10 | P11: =RIGHT(IF($E11<>"",_xlfn.XLOOKUP($E11,$C$4:$C$681,$B$4:$B$681,"NO LABEL"),BIN2HEX(IF(N11="CarryEn","1","0")&IF(M11="SubXY","1","0")&IF(H11<>"",VLOOKUP(H11,Ops!$F$2:'Ops'!$G$20,2,FALSE),"000000"),2)),2) -> 8F | Q11: {=BIN2HEX(_xlfn.IFS(D11="HWINTEN","10",G11="KeyAck","01",G11="InitLp8","01",TRUE,"00")&IF(OR(Ops!$O$2:'Ops'!$O$13=K11),VLOOKUP(K11,Ops!$O$2:'Ops'!$P$13,2,FALSE),"000")&IF(E11<>"",IF(LEN(_xlfn.XLOOKUP($E11,$C$5:$C$681,$B$5:$B$681,0))=3,HEX2BIN(LEFT(_xlfn.XLOOKUP($E11,$C$5:$C$681,$B$5:$B$681,0),1),3),IF(OR(Ops!$L$2:'Ops'!$L$11=J11),VLOOKUP(J11,Ops!$L$2:'Ops'!$M$11,2,FALSE),"000")),IF(OR(Ops!$L$2:'Ops'!$L$11=J11),VLOOKUP(J11,Ops!$L$2:'Ops'!$M$11,2,FALSE),"000")),2)} -> 41 | R11: 00 | S11: KeyAck reloads key capture reg (with 0) to Ack the Interrupt. | Z11: =IF(O11="", "};", "0x"&O11&",") -> 0x10, | AA11: ="0x"&P11&"," -> 0x8F, | AB11: ="0x"&Q11&"," -> 0x41, | AC11: 0x00,
A12: =A11+4 -> 24 | B12: =DEC2HEX(A12) -> 18 | D12: JMP | E12: SEVEN | G12: KeyAck | O12: {=BIN2HEX(IF(I12<>"",VLOOKUP(I12,Ops!$I$2:'Ops'!$J$13,2,FALSE),IF(ISNUMBER(SEARCH("BR",D12)),"001","000"))&IF(D12<>"",VLOOKUP(D12,Ops!$B$2:'Ops'!$C$23,2,FALSE),"0")&_xlfn.IFS(ISNUMBER(SEARCH("BR",D12)),VLOOKUP(D12,Ops!$B$3:'Ops'!$D$22,3,FALSE),F12<>"",VLOOKUP(F12,Ops!$R$2:'Ops'!$S$11,2),L12<>"",VLOOKUP(L12,Ops!$R$2:'Ops'!$S$25,2,FALSE),TRUE,"0000"),2)} -> 10 | P12: =RIGHT(IF($E12<>"",_xlfn.XLOOKUP($E12,$C$4:$C$681,$B$4:$B$681,"NO LABEL"),BIN2HEX(IF(N12="CarryEn","1","0")&IF(M12="SubXY","1","0")&IF(H12<>"",VLOOKUP(H12,Ops!$F$2:'Ops'!$G$20,2,FALSE),"000000"),2)),2) -> A1 | Q12: {=BIN2HEX(_xlfn.IFS(D12="HWINTEN","10",G12="KeyAck","01",G12="InitLp8","01",TRUE,"00")&IF(OR(Ops!$O$2:'Ops'!$O$13=K12),VLOOKUP(K12,Ops!$O$2:'Ops'!$P$13,2,FALSE),"000")&IF(E12<>"",IF(LEN(_xlfn.XLOOKUP($E12,$C$5:$C$681,$B$5:$B$681,0))=3,HEX2BIN(LEFT(_xlfn.XLOOKUP($E12,$C$5:$C$681,$B$5:$B$681,0),1),3),IF(OR(Ops!$L$2:'Ops'!$L$11=J12),VLOOKUP(J12,Ops!$L$2:'Ops'!$M$11,2,FALSE),"000")),IF(OR(Ops!$L$2:'Ops'!$L$11=J12),VLOOKUP(J12,Ops!$L$2:'Ops'!$M$11,2,FALSE),"000")),2)} -> 41 | R12: 00 | Z12: =IF(O12="", "};", "0x"&O12&",") -> 0x10, | AA12: ="0x"&P12&"," -> 0xA1, | AB12: ="0x"&Q12&"," -> 0x41, | AC12: 0x00,
A13: =A12+4 -> 28 | B13: =DEC2HEX(A13) -> 1C | D13: JMP | E13: ZERO | G13: KeyAck | O13: {=BIN2HEX(IF(I13<>"",VLOOKUP(I13,Ops!$I$2:'Ops'!$J$13,2,FALSE),IF(ISNUMBER(SEARCH("BR",D13)),"001","000"))&IF(D13<>"",VLOOKUP(D13,Ops!$B$2:'Ops'!$C$23,2,FALSE),"0")&_xlfn.IFS(ISNUMBER(SEARCH("BR",D13)),VLOOKUP(D13,Ops!$B$3:'Ops'!$D$22,3,FALSE),F13<>"",VLOOKUP(F13,Ops!$R$2:'Ops'!$S$11,2),L13<>"",VLOOKUP(L13,Ops!$R$2:'Ops'!$S$25,2,FALSE),TRUE,"0000"),2)} -> 10 | P13: =RIGHT(IF($E13<>"",_xlfn.XLOOKUP($E13,$C$4:$C$681,$B$4:$B$681,"NO LABEL"),BIN2HEX(IF(N13="CarryEn","1","0")&IF(M13="SubXY","1","0")&IF(H13<>"",VLOOKUP(H13,Ops!$F$2:'Ops'!$G$20,2,FALSE),"000000"),2)),2) -> 1D | Q13: {=BIN2HEX(_xlfn.IFS(D13="HWINTEN","10",G13="KeyAck","01",G13="InitLp8","01",TRUE,"00")&IF(OR(Ops!$O$2:'Ops'!$O$13=K13),VLOOKUP(K13,Ops!$O$2:'Ops'!$P$13,2,FALSE),"000")&IF(E13<>"",IF(LEN(_xlfn.XLOOKUP($E13,$C$5:$C$681,$B$5:$B$681,0))=3,HEX2BIN(LEFT(_xlfn.XLOOKUP($E13,$C$5:$C$681,$B$5:$B$681,0),1),3),IF(OR(Ops!$L$2:'Ops'!$L$11=J13),VLOOKUP(J13,Ops!$L$2:'Ops'!$M$11,2,FALSE),"000")),IF(OR(Ops!$L$2:'Ops'!$L$11=J13),VLOOKUP(J13,Ops!$L$2:'Ops'!$M$11,2,FALSE),"000")),2)} -> 41 | R13: 00 | Z13: =IF(O13="", "};", "0x"&O13&",") -> 0x10, | AA13: ="0x"&P13&"," -> 0x1D, | AB13: ="0x"&Q13&"," -> 0x41, | AC13: 0x00,
A14: =A13+4 -> 32 | B14: =DEC2HEX(A14) -> 20 | D14: JMP | E14: TWO | G14: KeyAck | O14: {=BIN2HEX(IF(I14<>"",VLOOKUP(I14,Ops!$I$2:'Ops'!$J$13,2,FALSE),IF(ISNUMBER(SEARCH("BR",D14)),"001","000"))&IF(D14<>"",VLOOKUP(D14,Ops!$B$2:'Ops'!$C$23,2,FALSE),"0")&_xlfn.IFS(ISNUMBER(SEARCH("BR",D14)),VLOOKUP(D14,Ops!$B$3:'Ops'!$D$22,3,FALSE),F14<>"",VLOOKUP(F14,Ops!$R$2:'Ops'!$S$11,2),L14<>"",VLOOKUP(L14,Ops!$R$2:'Ops'!$S$25,2,FALSE),TRUE,"0000"),2)} -> 10 | P14: =RIGHT(IF($E14<>"",_xlfn.XLOOKUP($E14,$C$4:$C$681,$B$4:$B$681,"NO LABEL"),BIN2HEX(IF(N14="CarryEn","1","0")&IF(M14="SubXY","1","0")&IF(H14<>"",VLOOKUP(H14,Ops!$F$2:'Ops'!$G$20,2,FALSE),"000000"),2)),2) -> 83 | Q14: {=BIN2HEX(_xlfn.IFS(D14="HWINTEN","10",G14="KeyAck","01",G14="InitLp8","01",TRUE,"00")&IF(OR(Ops!$O$2:'Ops'!$O$13=K14),VLOOKUP(K14,Ops!$O$2:'Ops'!$P$13,2,FALSE),"000")&IF(E14<>"",IF(LEN(_xlfn.XLOOKUP($E14,$C$5:$C$681,$B$5:$B$681,0))=3,HEX2BIN(LEFT(_xlfn.XLOOKUP($E14,$C$5:$C$681,$B$5:$B$681,0),1),3),IF(OR(Ops!$L$2:'Ops'!$L$11=J14),VLOOKUP(J14,Ops!$L$2:'Ops'!$M$11,2,FALSE),"000")),IF(OR(Ops!$L$2:'Ops'!$L$11=J14),VLOOKUP(J14,Ops!$L$2:'Ops'!$M$11,2,FALSE),"000")),2)} -> 41 | R14: 00 | Z14: =IF(O14="", "};", "0x"&O14&",") -> 0x10, | AA14: ="0x"&P14&"," -> 0x83, | AB14: ="0x"&Q14&"," -> 0x41, | AC14: 0x00,
A15: =A14+4 -> 36 | B15: =DEC2HEX(A15) -> 24 | D15: JMP | E15: FIVE | G15: KeyAck | O15: {=BIN2HEX(IF(I15<>"",VLOOKUP(I15,Ops!$I$2:'Ops'!$J$13,2,FALSE),IF(ISNUMBER(SEARCH("BR",D15)),"001","000"))&IF(D15<>"",VLOOKUP(D15,Ops!$B$2:'Ops'!$C$23,2,FALSE),"0")&_xlfn.IFS(ISNUMBER(SEARCH("BR",D15)),VLOOKUP(D15,Ops!$B$3:'Ops'!$D$22,3,FALSE),F15<>"",VLOOKUP(F15,Ops!$R$2:'Ops'!$S$11,2),L15<>"",VLOOKUP(L15,Ops!$R$2:'Ops'!$S$25,2,FALSE),TRUE,"0000"),2)} -> 10 | P15: =RIGHT(IF($E15<>"",_xlfn.XLOOKUP($E15,$C$4:$C$681,$B$4:$B$681,"NO LABEL"),BIN2HEX(IF(N15="CarryEn","1","0")&IF(M15="SubXY","1","0")&IF(H15<>"",VLOOKUP(H15,Ops!$F$2:'Ops'!$G$20,2,FALSE),"000000"),2)),2) -> 95 | Q15: {=BIN2HEX(_xlfn.IFS(D15="HWINTEN","10",G15="KeyAck","01",G15="InitLp8","01",TRUE,"00")&IF(OR(Ops!$O$2:'Ops'!$O$13=K15),VLOOKUP(K15,Ops!$O$2:'Ops'!$P$13,2,FALSE),"000")&IF(E15<>"",IF(LEN(_xlfn.XLOOKUP($E15,$C$5:$C$681,$B$5:$B$681,0))=3,HEX2BIN(LEFT(_xlfn.XLOOKUP($E15,$C$5:$C$681,$B$5:$B$681,0),1),3),IF(OR(Ops!$L$2:'Ops'!$L$11=J15),VLOOKUP(J15,Ops!$L$2:'Ops'!$M$11,2,FALSE),"000")),IF(OR(Ops!$L$2:'Ops'!$L$11=J15),VLOOKUP(J15,Ops!$L$2:'Ops'!$M$11,2,FALSE),"000")),2)} -> 41 | R15: 00 | Z15: =IF(O15="", "};", "0x"&O15&",") -> 0x10, | AA15: ="0x"&P15&"," -> 0x95, | AB15: ="0x"&Q15&"," -> 0x41, | AC15: 0x00,
A16: =A15+4 -> 40 | B16: =DEC2HEX(A16) -> 28 | D16: JMP | E16: EIGHT | G16: KeyAck | O16: {=BIN2HEX(IF(I16<>"",VLOOKUP(I16,Ops!$I$2:'Ops'!$J$13,2,FALSE),IF(ISNUMBER(SEARCH("BR",D16)),"001","000"))&IF(D16<>"",VLOOKUP(D16,Ops!$B$2:'Ops'!$C$23,2,FALSE),"0")&_xlfn.IFS(ISNUMBER(SEARCH("BR",D16)),VLOOKUP(D16,Ops!$B$3:'Ops'!$D$22,3,FALSE),F16<>"",VLOOKUP(F16,Ops!$R$2:'Ops'!$S$11,2),L16<>"",VLOOKUP(L16,Ops!$R$2:'Ops'!$S$25,2,FALSE),TRUE,"0000"),2)} -> 10 | P16: =RIGHT(IF($E16<>"",_xlfn.XLOOKUP($E16,$C$4:$C$681,$B$4:$B$681,"NO LABEL"),BIN2HEX(IF(N16="CarryEn","1","0")&IF(M16="SubXY","1","0")&IF(H16<>"",VLOOKUP(H16,Ops!$F$2:'Ops'!$G$20,2,FALSE),"000000"),2)),2) -> A7 | Q16: {=BIN2HEX(_xlfn.IFS(D16="HWINTEN","10",G16="KeyAck","01",G16="InitLp8","01",TRUE,"00")&IF(OR(Ops!$O$2:'Ops'!$O$13=K16),VLOOKUP(K16,Ops!$O$2:'Ops'!$P$13,2,FALSE),"000")&IF(E16<>"",IF(LEN(_xlfn.XLOOKUP($E16,$C$5:$C$681,$B$5:$B$681,0))=3,HEX2BIN(LEFT(_xlfn.XLOOKUP($E16,$C$5:$C$681,$B$5:$B$681,0),1),3),IF(OR(Ops!$L$2:'Ops'!$L$11=J16),VLOOKUP(J16,Ops!$L$2:'Ops'!$M$11,2,FALSE),"000")),IF(OR(Ops!$L$2:'Ops'!$L$11=J16),VLOOKUP(J16,Ops!$L$2:'Ops'!$M$11,2,FALSE),"000")),2)} -> 41 | R16: 00 | Z16: =IF(O16="", "};", "0x"&O16&",") -> 0x10, | AA16: ="0x"&P16&"," -> 0xA7, | AB16: ="0x"&Q16&"," -> 0x41, | AC16: 0x00,
A17: =A16+4 -> 44 | B17: =DEC2HEX(A17) -> 2C | D17: JMP | E17: DP | G17: KeyAck | O17: {=BIN2HEX(IF(I17<>"",VLOOKUP(I17,Ops!$I$2:'Ops'!$J$13,2,FALSE),IF(ISNUMBER(SEARCH("BR",D17)),"001","000"))&IF(D17<>"",VLOOKUP(D17,Ops!$B$2:'Ops'!$C$23,2,FALSE),"0")&_xlfn.IFS(ISNUMBER(SEARCH("BR",D17)),VLOOKUP(D17,Ops!$B$3:'Ops'!$D$22,3,FALSE),F17<>"",VLOOKUP(F17,Ops!$R$2:'Ops'!$S$11,2),L17<>"",VLOOKUP(L17,Ops!$R$2:'Ops'!$S$25,2,FALSE),TRUE,"0000"),2)} -> 10 | P17: =RIGHT(IF($E17<>"",_xlfn.XLOOKUP($E17,$C$4:$C$681,$B$4:$B$681,"NO LABEL"),BIN2HEX(IF(N17="CarryEn","1","0")&IF(M17="SubXY","1","0")&IF(H17<>"",VLOOKUP(H17,Ops!$F$2:'Ops'!$G$20,2,FALSE),"000000"),2)),2) -> 01 | Q17: {=BIN2HEX(_xlfn.IFS(D17="HWINTEN","10",G17="KeyAck","01",G17="InitLp8","01",TRUE,"00")&IF(OR(Ops!$O$2:'Ops'!$O$13=K17),VLOOKUP(K17,Ops!$O$2:'Ops'!$P$13,2,FALSE),"000")&IF(E17<>"",IF(LEN(_xlfn.XLOOKUP($E17,$C$5:$C$681,$B$5:$B$681,0))=3,HEX2BIN(LEFT(_xlfn.XLOOKUP($E17,$C$5:$C$681,$B$5:$B$681,0),1),3),IF(OR(Ops!$L$2:'Ops'!$L$11=J17),VLOOKUP(J17,Ops!$L$2:'Ops'!$M$11,2,FALSE),"000")),IF(OR(Ops!$L$2:'Ops'!$L$11=J17),VLOOKUP(J17,Ops!$L$2:'Ops'!$M$11,2,FALSE),"000")),2)} -> 42 | R17: 00 | Z17: =IF(O17="", "};", "0x"&O17&",") -> 0x10, | AA17: ="0x"&P17&"," -> 0x01, | AB17: ="0x"&Q17&"," -> 0x42, | AC17: 0x00,
A18: =A17+4 -> 48 | B18: =DEC2HEX(A18) -> 30 | D18: JMP | E18: THREE | G18: KeyAck | O18: {=BIN2HEX(IF(I18<>"",VLOOKUP(I18,Ops!$I$2:'Ops'!$J$13,2,FALSE),IF(ISNUMBER(SEARCH("BR",D18)),"001","000"))&IF(D18<>"",VLOOKUP(D18,Ops!$B$2:'Ops'!$C$23,2,FALSE),"0")&_xlfn.IFS(ISNUMBER(SEARCH("BR",D18)),VLOOKUP(D18,Ops!$B$3:'Ops'!$D$22,3,FALSE),F18<>"",VLOOKUP(F18,Ops!$R$2:'Ops'!$S$11,2),L18<>"",VLOOKUP(L18,Ops!$R$2:'Ops'!$S$25,2,FALSE),TRUE,"0000"),2)} -> 10 | P18: =RIGHT(IF($E18<>"",_xlfn.XLOOKUP($E18,$C$4:$C$681,$B$4:$B$681,"NO LABEL"),BIN2HEX(IF(N18="CarryEn","1","0")&IF(M18="SubXY","1","0")&IF(H18<>"",VLOOKUP(H18,Ops!$F$2:'Ops'!$G$20,2,FALSE),"000000"),2)),2) -> 89 | Q18: {=BIN2HEX(_xlfn.IFS(D18="HWINTEN","10",G18="KeyAck","01",G18="InitLp8","01",TRUE,"00")&IF(OR(Ops!$O$2:'Ops'!$O$13=K18),VLOOKUP(K18,Ops!$O$2:'Ops'!$P$13,2,FALSE),"000")&IF(E18<>"",IF(LEN(_xlfn.XLOOKUP($E18,$C$5:$C$681,$B$5:$B$681,0))=3,HEX2BIN(LEFT(_xlfn.XLOOKUP($E18,$C$5:$C$681,$B$5:$B$681,0),1),3),IF(OR(Ops!$L$2:'Ops'!$L$11=J18),VLOOKUP(J18,Ops!$L$2:'Ops'!$M$11,2,FALSE),"000")),IF(OR(Ops!$L$2:'Ops'!$L$11=J18),VLOOKUP(J18,Ops!$L$2:'Ops'!$M$11,2,FALSE),"000")),2)} -> 41 | R18: 00 | Z18: =IF(O18="", "};", "0x"&O18&",") -> 0x10, | AA18: ="0x"&P18&"," -> 0x89, | AB18: ="0x"&Q18&"," -> 0x41, | AC18: 0x00,
A19: =A18+4 -> 52 | B19: =DEC2HEX(A19) -> 34 | D19: JMP | E19: SIX | G19: KeyAck | O19: {=BIN2HEX(IF(I19<>"",VLOOKUP(I19,Ops!$I$2:'Ops'!$J$13,2,FALSE),IF(ISNUMBER(SEARCH("BR",D19)),"001","000"))&IF(D19<>"",VLOOKUP(D19,Ops!$B$2:'Ops'!$C$23,2,FALSE),"0")&_xlfn.IFS(ISNUMBER(SEARCH("BR",D19)),VLOOKUP(D19,Ops!$B$3:'Ops'!$D$22,3,FALSE),F19<>"",VLOOKUP(F19,Ops!$R$2:'Ops'!$S$11,2),L19<>"",VLOOKUP(L19,Ops!$R$2:'Ops'!$S$25,2,FALSE),TRUE,"0000"),2)} -> 10 | P19: =RIGHT(IF($E19<>"",_xlfn.XLOOKUP($E19,$C$4:$C$681,$B$4:$B$681,"NO LABEL"),BIN2HEX(IF(N19="CarryEn","1","0")&IF(M19="SubXY","1","0")&IF(H19<>"",VLOOKUP(H19,Ops!$F$2:'Ops'!$G$20,2,FALSE),"000000"),2)),2) -> 9B | Q19: {=BIN2HEX(_xlfn.IFS(D19="HWINTEN","10",G19="KeyAck","01",G19="InitLp8","01",TRUE,"00")&IF(OR(Ops!$O$2:'Ops'!$O$13=K19),VLOOKUP(K19,Ops!$O$2:'Ops'!$P$13,2,FALSE),"000")&IF(E19<>"",IF(LEN(_xlfn.XLOOKUP($E19,$C$5:$C$681,$B$5:$B$681,0))=3,HEX2BIN(LEFT(_xlfn.XLOOKUP($E19,$C$5:$C$681,$B$5:$B$681,0),1),3),IF(OR(Ops!$L$2:'Ops'!$L$11=J19),VLOOKUP(J19,Ops!$L$2:'Ops'!$M$11,2,FALSE),"000")),IF(OR(Ops!$L$2:'Ops'!$L$11=J19),VLOOKUP(J19,Ops!$L$2:'Ops'!$M$11,2,FALSE),"000")),2)} -> 41 | R19: 00 | Z19: =IF(O19="", "};", "0x"&O19&",") -> 0x10, | AA19: ="0x"&P19&"," -> 0x9B, | AB19: ="0x"&Q19&"," -> 0x41, | AC19: 0x00,
A20: =A19+4 -> 56 | B20: =DEC2HEX(A20) -> 38 | D20: JMP | E20: NINE | G20: KeyAck | O20: {=BIN2HEX(IF(I20<>"",VLOOKUP(I20,Ops!$I$2:'Ops'!$J$13,2,FALSE),IF(ISNUMBER(SEARCH("BR",D20)),"001","000"))&IF(D20<>"",VLOOKUP(D20,Ops!$B$2:'Ops'!$C$23,2,FALSE),"0")&_xlfn.IFS(ISNUMBER(SEARCH("BR",D20)),VLOOKUP(D20,Ops!$B$3:'Ops'!$D$22,3,FALSE),F20<>"",VLOOKUP(F20,Ops!$R$2:'Ops'!$S$11,2),L20<>"",VLOOKUP(L20,Ops!$R$2:'Ops'!$S$25,2,FALSE),TRUE,"0000"),2)} -> 10 | P20: =RIGHT(IF($E20<>"",_xlfn.XLOOKUP($E20,$C$4:$C$681,$B$4:$B$681,"NO LABEL"),BIN2HEX(IF(N20="CarryEn","1","0")&IF(M20="SubXY","1","0")&IF(H20<>"",VLOOKUP(H20,Ops!$F$2:'Ops'!$G$20,2,FALSE),"000000"),2)),2) -> AD | Q20: {=BIN2HEX(_xlfn.IFS(D20="HWINTEN","10",G20="KeyAck","01",G20="InitLp8","01",TRUE,"00")&IF(OR(Ops!$O$2:'Ops'!$O$13=K20),VLOOKUP(K20,Ops!$O$2:'Ops'!$P$13,2,FALSE),"000")&IF(E20<>"",IF(LEN(_xlfn.XLOOKUP($E20,$C$5:$C$681,$B$5:$B$681,0))=3,HEX2BIN(LEFT(_xlfn.XLOOKUP($E20,$C$5:$C$681,$B$5:$B$681,0),1),3),IF(OR(Ops!$L$2:'Ops'!$L$11=J20),VLOOKUP(J20,Ops!$L$2:'Ops'!$M$11,2,FALSE),"000")),IF(OR(Ops!$L$2:'Ops'!$L$11=J20),VLOOKUP(J20,Ops!$L$2:'Ops'!$M$11,2,FALSE),"000")),2)} -> 41 | R20: 00 | Z20: =IF(O20="", "};", "0x"&O20&",") -> 0x10, | AA20: ="0x"&P20&"," -> 0xAD, | AB20: ="0x"&Q20&"," -> 0x41, | AC20: 0x00,
A21: =A20+4 -> 60 | B21: =DEC2HEX(A21) -> 3C | D21: JMP | E21: ENTOP1 | G21: KeyAck | O21: {=BIN2HEX(IF(I21<>"",VLOOKUP(I21,Ops!$I$2:'Ops'!$J$13,2,FALSE),IF(ISNUMBER(SEARCH("BR",D21)),"001","000"))&IF(D21<>"",VLOOKUP(D21,Ops!$B$2:'Ops'!$C$23,2,FALSE),"0")&_xlfn.IFS(ISNUMBER(SEARCH("BR",D21)),VLOOKUP(D21,Ops!$B$3:'Ops'!$D$22,3,FALSE),F21<>"",VLOOKUP(F21,Ops!$R$2:'Ops'!$S$11,2),L21<>"",VLOOKUP(L21,Ops!$R$2:'Ops'!$S$25,2,FALSE),TRUE,"0000"),2)} -> 10 | P21: =RIGHT(IF($E21<>"",_xlfn.XLOOKUP($E21,$C$4:$C$681,$B$4:$B$681,"NO LABEL"),BIN2HEX(IF(N21="CarryEn","1","0")&IF(M21="SubXY","1","0")&IF(H21<>"",VLOOKUP(H21,Ops!$F$2:'Ops'!$G$20,2,FALSE),"000000"),2)),2) -> A3 | Q21: {=BIN2HEX(_xlfn.IFS(D21="HWINTEN","10",G21="KeyAck","01",G21="InitLp8","01",TRUE,"00")&IF(OR(Ops!$O$2:'Ops'!$O$13=K21),VLOOKUP(K21,Ops!$O$2:'Ops'!$P$13,2,FALSE),"000")&IF(E21<>"",IF(LEN(_xlfn.XLOOKUP($E21,$C$5:$C$681,$B$5:$B$681,0))=3,HEX2BIN(LEFT(_xlfn.XLOOKUP($E21,$C$5:$C$681,$B$5:$B$681,0),1),3),IF(OR(Ops!$L$2:'Ops'!$L$11=J21),VLOOKUP(J21,Ops!$L$2:'Ops'!$M$11,2,FALSE),"000")),IF(OR(Ops!$L$2:'Ops'!$L$11=J21),VLOOKUP(J21,Ops!$L$2:'Ops'!$M$11,2,FALSE),"000")),2)} -> 42 | R21: 00 | Z21: =IF(O21="", "};", "0x"&O21&",") -> 0x10, | AA21: ="0x"&P21&"," -> 0xA3, | AB21: ="0x"&Q21&"," -> 0x42, | AC21: 0x00,
A22: =A21+4 -> 64 | B22: =DEC2HEX(A22) -> 40 | D22: JMP | E22: PLUS | G22: KeyAck | O22: {=BIN2HEX(IF(I22<>"",VLOOKUP(I22,Ops!$I$2:'Ops'!$J$13,2,FALSE),IF(ISNUMBER(SEARCH("BR",D22)),"001","000"))&IF(D22<>"",VLOOKUP(D22,Ops!$B$2:'Ops'!$C$23,2,FALSE),"0")&_xlfn.IFS(ISNUMBER(SEARCH("BR",D22)),VLOOKUP(D22,Ops!$B$3:'Ops'!$D$22,3,FALSE),F22<>"",VLOOKUP(F22,Ops!$R$2:'Ops'!$S$11,2),L22<>"",VLOOKUP(L22,Ops!$R$2:'Ops'!$S$25,2,FALSE),TRUE,"0000"),2)} -> 10 | P22: =RIGHT(IF($E22<>"",_xlfn.XLOOKUP($E22,$C$4:$C$681,$B$4:$B$681,"NO LABEL"),BIN2HEX(IF(N22="CarryEn","1","0")&IF(M22="SubXY","1","0")&IF(H22<>"",VLOOKUP(H22,Ops!$F$2:'Ops'!$G$20,2,FALSE),"000000"),2)),2) -> 33 | Q22: {=BIN2HEX(_xlfn.IFS(D22="HWINTEN","10",G22="KeyAck","01",G22="InitLp8","01",TRUE,"00")&IF(OR(Ops!$O$2:'Ops'!$O$13=K22),VLOOKUP(K22,Ops!$O$2:'Ops'!$P$13,2,FALSE),"000")&IF(E22<>"",IF(LEN(_xlfn.XLOOKUP($E22,$C$5:$C$681,$B$5:$B$681,0))=3,HEX2BIN(LEFT(_xlfn.XLOOKUP($E22,$C$5:$C$681,$B$5:$B$681,0),1),3),IF(OR(Ops!$L$2:'Ops'!$L$11=J22),VLOOKUP(J22,Ops!$L$2:'Ops'!$M$11,2,FALSE),"000")),IF(OR(Ops!$L$2:'Ops'!$L$11=J22),VLOOKUP(J22,Ops!$L$2:'Ops'!$M$11,2,FALSE),"000")),2)} -> 43 | R22: 00 | Z22: =IF(O22="", "};", "0x"&O22&",") -> 0x10, | AA22: ="0x"&P22&"," -> 0x33, | AB22: ="0x"&Q22&"," -> 0x43, | AC22: 0x00,
A23: =A22+4 -> 68 | B23: =DEC2HEX(A23) -> 44 | D23: JMP | E23: MINUS | G23: KeyAck | O23: {=BIN2HEX(IF(I23<>"",VLOOKUP(I23,Ops!$I$2:'Ops'!$J$13,2,FALSE),IF(ISNUMBER(SEARCH("BR",D23)),"001","000"))&IF(D23<>"",VLOOKUP(D23,Ops!$B$2:'Ops'!$C$23,2,FALSE),"0")&_xlfn.IFS(ISNUMBER(SEARCH("BR",D23)),VLOOKUP(D23,Ops!$B$3:'Ops'!$D$22,3,FALSE),F23<>"",VLOOKUP(F23,Ops!$R$2:'Ops'!$S$11,2),L23<>"",VLOOKUP(L23,Ops!$R$2:'Ops'!$S$25,2,FALSE),TRUE,"0000"),2)} -> 10 | P23: =RIGHT(IF($E23<>"",_xlfn.XLOOKUP($E23,$C$4:$C$681,$B$4:$B$681,"NO LABEL"),BIN2HEX(IF(N23="CarryEn","1","0")&IF(M23="SubXY","1","0")&IF(H23<>"",VLOOKUP(H23,Ops!$F$2:'Ops'!$G$20,2,FALSE),"000000"),2)),2) -> 12 | Q23: {=BIN2HEX(_xlfn.IFS(D23="HWINTEN","10",G23="KeyAck","01",G23="InitLp8","01",TRUE,"00")&IF(OR(Ops!$O$2:'Ops'!$O$13=K23),VLOOKUP(K23,Ops!$O$2:'Ops'!$P$13,2,FALSE),"000")&IF(E23<>"",IF(LEN(_xlfn.XLOOKUP($E23,$C$5:$C$681,$B$5:$B$681,0))=3,HEX2BIN(LEFT(_xlfn.XLOOKUP($E23,$C$5:$C$681,$B$5:$B$681,0),1),3),IF(OR(Ops!$L$2:'Ops'!$L$11=J23),VLOOKUP(J23,Ops!$L$2:'Ops'!$M$11,2,FALSE),"000")),IF(OR(Ops!$L$2:'Ops'!$L$11=J23),VLOOKUP(J23,Ops!$L$2:'Ops'!$M$11,2,FALSE),"000")),2)} -> 43 | R23: 00 | Z23: =IF(O23="", "};", "0x"&O23&",") -> 0x10, | AA23: ="0x"&P23&"," -> 0x12, | AB23: ="0x"&Q23&"," -> 0x43, | AC23: 0x00,
... A27: =A26+4 -> 84 | B27: =DEC2HEX(A27) -> 54 | D27: JMP | E27: CE | G27: KeyAck | O27: {=BIN2HEX(IF(I27<>"",VLOOKUP(I27,Ops!$I$2:'Ops'!$J$13,2,FALSE),IF(ISNUMBER(SEARCH("BR",D27)),"001","000"))&IF(D27<>"",VLOOKUP(D27,Ops!$B$2:'Ops'!$C$23,2,FALSE),"0")&_xlfn.IFS(ISNUMBER(SEARCH("BR",D27)),VLOOKUP(D27,Ops!$B$3:'Ops'!$D$22,3,FALSE),F27<>"",VLOOKUP(F27,Ops!$R$2:'Ops'!$S$11,2),L27<>"",VLOOKUP(L27,Ops!$R$2:'Ops'!$S$25,2,FALSE),TRUE,"0000"),2)} -> 10 | P27: =RIGHT(IF($E27<>"",_xlfn.XLOOKUP($E27,$C$4:$C$681,$B$4:$B$681,"NO LABEL"),BIN2HEX(IF(N27="CarryEn","1","0")&IF(M27="SubXY","1","0")&IF(H27<>"",VLOOKUP(H27,Ops!$F$2:'Ops'!$G$20,2,FALSE),"000000"),2)),2) -> 3D | Q27: {=BIN2HEX(_xlfn.IFS(D27="HWINTEN","10",G27="KeyAck","01",G27="InitLp8","01",TRUE,"00")&IF(OR(Ops!$O$2:'Ops'!$O$13=K27),VLOOKUP(K27,Ops!$O$2:'Ops'!$P$13,2,FALSE),"000")&IF(E27<>"",IF(LEN(_xlfn.XLOOKUP($E27,$C$5:$C$681,$B$5:$B$681,0))=3,HEX2BIN(LEFT(_xlfn.XLOOKUP($E27,$C$5:$C$681,$B$5:$B$681,0),1),3),IF(OR(Ops!$L$2:'Ops'!$L$11=J27),VLOOKUP(J27,Ops!$L$2:'Ops'!$M$11,2,FALSE),"000")),IF(OR(Ops!$L$2:'Ops'!$L$11=J27),VLOOKUP(J27,Ops!$L$2:'Ops'!$M$11,2,FALSE),"000")),2)} -> 42 | R27: 00 | Z27: =IF(O27="", "};", "0x"&O27&",") -> 0x10, | AA27: ="0x"&P27&"," -> 0x3D, | AB27: ="0x"&Q27&"," -> 0x42, | AC27: 0x00,
A28: =A27+4 -> 88 | B28: =DEC2HEX(A28) -> 58 | C28: X2 | D28: JMP | E28: CLR | G28: KeyAck | O28: {=BIN2HEX(IF(I28<>"",VLOOKUP(I28,Ops!$I$2:'Ops'!$J$13,2,FALSE),IF(ISNUMBER(SEARCH("BR",D28)),"001","000"))&IF(D28<>"",VLOOKUP(D28,Ops!$B$2:'Ops'!$C$23,2,FALSE),"0")&_xlfn.IFS(ISNUMBER(SEARCH("BR",D28)),VLOOKUP(D28,Ops!$B$3:'Ops'!$D$22,3,FALSE),F28<>"",VLOOKUP(F28,Ops!$R$2:'Ops'!$S$11,2),L28<>"",VLOOKUP(L28,Ops!$R$2:'Ops'!$S$25,2,FALSE),TRUE,"0000"),2)} -> 10 | P28: =RIGHT(IF($E28<>"",_xlfn.XLOOKUP($E28,$C$4:$C$681,$B$4:$B$681,"NO LABEL"),BIN2HEX(IF(N28="CarryEn","1","0")&IF(M28="SubXY","1","0")&IF(H28<>"",VLOOKUP(H28,Ops!$F$2:'Ops'!$G$20,2,FALSE),"000000"),2)),2) -> 2B | Q28: {=BIN2HEX(_xlfn.IFS(D28="HWINTEN","10",G28="KeyAck","01",G28="InitLp8","01",TRUE,"00")&IF(OR(Ops!$O$2:'Ops'!$O$13=K28),VLOOKUP(K28,Ops!$O$2:'Ops'!$P$13,2,FALSE),"000")&IF(E28<>"",IF(LEN(_xlfn.XLOOKUP($E28,$C$5:$C$681,$B$5:$B$681,0))=3,HEX2BIN(LEFT(_xlfn.XLOOKUP($E28,$C$5:$C$681,$B$5:$B$681,0),1),3),IF(OR(Ops!$L$2:'Ops'!$L$11=J28),VLOOKUP(J28,Ops!$L$2:'Ops'!$M$11,2,FALSE),"000")),IF(OR(Ops!$L$2:'Ops'!$L$11=J28),VLOOKUP(J28,Ops!$L$2:'Ops'!$M$11,2,FALSE),"000")),2)} -> 42 | R28: 00 | Z28: =IF(O28="", "};", "0x"&O28&",") -> 0x10, | AA28: ="0x"&P28&"," -> 0x2B, | AB28: ="0x"&Q28&"," -> 0x42, | AC28: 0x00,
A29: =A28+4 -> 92 | B29: =DEC2HEX(A29) -> 5C | C29: X3 | D29: JMP | E29: CLR | G29: KeyAck | O29: {=BIN2HEX(IF(I29<>"",VLOOKUP(I29,Ops!$I$2:'Ops'!$J$13,2,FALSE),IF(ISNUMBER(SEARCH("BR",D29)),"001","000"))&IF(D29<>"",VLOOKUP(D29,Ops!$B$2:'Ops'!$C$23,2,FALSE),"0")&_xlfn.IFS(ISNUMBER(SEARCH("BR",D29)),VLOOKUP(D29,Ops!$B$3:'Ops'!$D$22,3,FALSE),F29<>"",VLOOKUP(F29,Ops!$R$2:'Ops'!$S$11,2),L29<>"",VLOOKUP(L29,Ops!$R$2:'Ops'!$S$25,2,FALSE),TRUE,"0000"),2)} -> 10 | P29: =RIGHT(IF($E29<>"",_xlfn.XLOOKUP($E29,$C$4:$C$681,$B$4:$B$681,"NO LABEL"),BIN2HEX(IF(N29="CarryEn","1","0")&IF(M29="SubXY","1","0")&IF(H29<>"",VLOOKUP(H29,Ops!$F$2:'Ops'!$G$20,2,FALSE),"000000"),2)),2) -> 2B | Q29: {=BIN2HEX(_xlfn.IFS(D29="HWINTEN","10",G29="KeyAck","01",G29="InitLp8","01",TRUE,"00")&IF(OR(Ops!$O$2:'Ops'!$O$13=K29),VLOOKUP(K29,Ops!$O$2:'Ops'!$P$13,2,FALSE),"000")&IF(E29<>"",IF(LEN(_xlfn.XLOOKUP($E29,$C$5:$C$681,$B$5:$B$681,0))=3,HEX2BIN(LEFT(_xlfn.XLOOKUP($E29,$C$5:$C$681,$B$5:$B$681,0),1),3),IF(OR(Ops!$L$2:'Ops'!$L$11=J29),VLOOKUP(J29,Ops!$L$2:'Ops'!$M$11,2,FALSE),"000")),IF(OR(Ops!$L$2:'Ops'!$L$11=J29),VLOOKUP(J29,Ops!$L$2:'Ops'!$M$11,2,FALSE),"000")),2)} -> 42 | R29: 00 | Z29: =IF(O29="", "};", "0x"&O29&",") -> 0x10, | AA29: ="0x"&P29&"," -> 0x2B, | AB29: ="0x"&Q29&"," -> 0x42, | AC29: 0x00,
A30: =A29+4 -> 96 | B30: =DEC2HEX(A30) -> 60 | C30: DSKY | D30: HWINTEN | F30: 9 | O30: {=BIN2HEX(IF(I30<>"",VLOOKUP(I30,Ops!$I$2:'Ops'!$J$13,2,FALSE),IF(ISNUMBER(SEARCH("BR",D30)),"001","000"))&IF(D30<>"",VLOOKUP(D30,Ops!$B$2:'Ops'!$C$23,2,FALSE),"0")&_xlfn.IFS(ISNUMBER(SEARCH("BR",D30)),VLOOKUP(D30,Ops!$B$3:'Ops'!$D$22,3,FALSE),F30<>"",VLOOKUP(F30,Ops!$R$2:'Ops'!$S$11,2),L30<>"",VLOOKUP(L30,Ops!$R$2:'Ops'!$S$25,2,FALSE),TRUE,"0000"),2)} -> 09 | P30: =RIGHT(IF($E30<>"",_xlfn.XLOOKUP($E30,$C$4:$C$681,$B$4:$B$681,"NO LABEL"),BIN2HEX(IF(N30="CarryEn","1","0")&IF(M30="SubXY","1","0")&IF(H30<>"",VLOOKUP(H30,Ops!$F$2:'Ops'!$G$20,2,FALSE),"000000"),2)),2) -> 00 | Q30: {=BIN2HEX(_xlfn.IFS(D30="HWINTEN","10",G30="KeyAck","01",G30="InitLp8","01",TRUE,"00")&IF(OR(Ops!$O$2:'Ops'!$O$13=K30),VLOOKUP(K30,Ops!$O$2:'Ops'!$P$13,2,FALSE),"000")&IF(E30<>"",IF(LEN(_xlfn.XLOOKUP($E30,$C$5:$C$681,$B$5:$B$681,0))=3,HEX2BIN(LEFT(_xlfn.XLOOKUP($E30,$C$5:$C$681,$B$5:$B$681,0),1),3),IF(OR(Ops!$L$2:'Ops'!$L$11=J30),VLOOKUP(J30,Ops!$L$2:'Ops'!$M$11,2,FALSE),"000")),IF(OR(Ops!$L$2:'Ops'!$L$11=J30),VLOOKUP(J30,Ops!$L$2:'Ops'!$M$11,2,FALSE),"000")),2)} -> 80 | S30: DSKY loop. Enable interrupt. Turn display ON | Z30: =IF(O30="", "};", "0x"&O30&",") -> 0x09, | AA30: ="0x"&P30&"," -> 0x00, | AB30: ="0x"&Q30&"," -> 0x80,
A31: =A30+3 -> 99 | B31: =DEC2HEX(A31) -> 63 | F31: 0 | O31: {=BIN2HEX(IF(I31<>"",VLOOKUP(I31,Ops!$I$2:'Ops'!$J$13,2,FALSE),IF(ISNUMBER(SEARCH("BR",D31)),"001","000"))&IF(D31<>"",VLOOKUP(D31,Ops!$B$2:'Ops'!$C$23,2,FALSE),"0")&_xlfn.IFS(ISNUMBER(SEARCH("BR",D31)),VLOOKUP(D31,Ops!$B$3:'Ops'!$D$22,3,FALSE),F31<>"",VLOOKUP(F31,Ops!$R$2:'Ops'!$S$11,2),L31<>"",VLOOKUP(L31,Ops!$R$2:'Ops'!$S$25,2,FALSE),TRUE,"0000"),2)} -> 00 | P31: =RIGHT(IF($E31<>"",_xlfn.XLOOKUP($E31,$C$4:$C$681,$B$4:$B$681,"NO LABEL"),BIN2HEX(IF(N31="CarryEn","1","0")&IF(M31="SubXY","1","0")&IF(H31<>"",VLOOKUP(H31,Ops!$F$2:'Ops'!$G$20,2,FALSE),"000000"),2)),2) -> 00 | Q31: {=BIN2HEX(_xlfn.IFS(D31="HWINTEN","10",G31="KeyAck","01",G31="InitLp8","01",TRUE,"00")&IF(OR(Ops!$O$2:'Ops'!$O$13=K31),VLOOKUP(K31,Ops!$O$2:'Ops'!$P$13,2,FALSE),"000")&IF(E31<>"",IF(LEN(_xlfn.XLOOKUP($E31,$C$5:$C$681,$B$5:$B$681,0))=3,HEX2BIN(LEFT(_xlfn.XLOOKUP($E31,$C$5:$C$681,$B$5:$B$681,0),1),3),IF(OR(Ops!$L$2:'Ops'!$L$11=J31),VLOOKUP(J31,Ops!$L$2:'Ops'!$M$11,2,FALSE),"000")),IF(OR(Ops!$L$2:'Ops'!$L$11=J31),VLOOKUP(J31,Ops!$L$2:'Ops'!$M$11,2,FALSE),"000")),2)} -> 00 | S31: Light up XDig1 | Z31: =IF(O31="", "};", "0x"&O31&",") -> 0x00, | AA31: ="0x"&P31&"," -> 0x00, | AB31: ="0x"&Q31&"," -> 0x00,
A32: =A31+3 -> 102 | B32: =DEC2HEX(A32) -> 66 | F32: 0 | O32: {=BIN2HEX(IF(I32<>"",VLOOKUP(I32,Ops!$I$2:'Ops'!$J$13,2,FALSE),IF(ISNUMBER(SEARCH("BR",D32)),"001","000"))&IF(D32<>"",VLOOKUP(D32,Ops!$B$2:'Ops'!$C$23,2,FALSE),"0")&_xlfn.IFS(ISNUMBER(SEARCH("BR",D32)),VLOOKUP(D32,Ops!$B$3:'Ops'!$D$22,3,FALSE),F32<>"",VLOOKUP(F32,Ops!$R$2:'Ops'!$S$11,2),L32<>"",VLOOKUP(L32,Ops!$R$2:'Ops'!$S$25,2,FALSE),TRUE,"0000"),2)} -> 00 | P32: =RIGHT(IF($E32<>"",_xlfn.XLOOKUP($E32,$C$4:$C$681,$B$4:$B$681,"NO LABEL"),BIN2HEX(IF(N32="CarryEn","1","0")&IF(M32="SubXY","1","0")&IF(H32<>"",VLOOKUP(H32,Ops!$F$2:'Ops'!$G$20,2,FALSE),"000000"),2)),2) -> 00 | Q32: {=BIN2HEX(_xlfn.IFS(D32="HWINTEN","10",G32="KeyAck","01",G32="InitLp8","01",TRUE,"00")&IF(OR(Ops!$O$2:'Ops'!$O$13=K32),VLOOKUP(K32,Ops!$O$2:'Ops'!$P$13,2,FALSE),"000")&IF(E32<>"",IF(LEN(_xlfn.XLOOKUP($E32,$C$5:$C$681,$B$5:$B$681,0))=3,HEX2BIN(LEFT(_xlfn.XLOOKUP($E32,$C$5:$C$681,$B$5:$B$681,0),1),3),IF(OR(Ops!$L$2:'Ops'!$L$11=J32),VLOOKUP(J32,Ops!$L$2:'Ops'!$M$11,2,FALSE),"000")),IF(OR(Ops!$L$2:'Ops'!$L$11=J32),VLOOKUP(J32,Ops!$L$2:'Ops'!$M$11,2,FALSE),"000")),2)} -> 00 | S32: Repeating display select to increas duty cycle | Z32: =IF(O32="", "};", "0x"&O32&",") -> 0x00, | AA32: ="0x"&P32&"," -> 0x00, | AB32: ="0x"&Q32&"," -> 0x00,
A33: =A32+3 -> 105 | B33: =DEC2HEX(A33) -> 69 | F33: 0 | O33: {=BIN2HEX(IF(I33<>"",VLOOKUP(I33,Ops!$I$2:'Ops'!$J$13,2,FALSE),IF(ISNUMBER(SEARCH("BR",D33)),"001","000"))&IF(D33<>"",VLOOKUP(D33,Ops!$B$2:'Ops'!$C$23,2,FALSE),"0")&_xlfn.IFS(ISNUMBER(SEARCH("BR",D33)),VLOOKUP(D33,Ops!$B$3:'Ops'!$D$22,3,FALSE),F33<>"",VLOOKUP(F33,Ops!$R$2:'Ops'!$S$11,2),L33<>"",VLOOKUP(L33,Ops!$R$2:'Ops'!$S$25,2,FALSE),TRUE,"0000"),2)} -> 00 | P33: =RIGHT(IF($E33<>"",_xlfn.XLOOKUP($E33,$C$4:$C$681,$B$4:$B$681,"NO LABEL"),BIN2HEX(IF(N33="CarryEn","1","0")&IF(M33="SubXY","1","0")&IF(H33<>"",VLOOKUP(H33,Ops!$F$2:'Ops'!$G$20,2,FALSE),"000000"),2)),2) -> 00 | Q33: {=BIN2HEX(_xlfn.IFS(D33="HWINTEN","10",G33="KeyAck","01",G33="InitLp8","01",TRUE,"00")&IF(OR(Ops!$O$2:'Ops'!$O$13=K33),VLOOKUP(K33,Ops!$O$2:'Ops'!$P$13,2,FALSE),"000")&IF(E33<>"",IF(LEN(_xlfn.XLOOKUP($E33,$C$5:$C$681,$B$5:$B$681,0))=3,HEX2BIN(LEFT(_xlfn.XLOOKUP($E33,$C$5:$C$681,$B$5:$B$681,0),1),3),IF(OR(Ops!$L$2:'Ops'!$L$11=J33),VLOOKUP(J33,Ops!$L$2:'Ops'!$M$11,2,FALSE),"000")),IF(OR(Ops!$L$2:'Ops'!$L$11=J33),VLOOKUP(J33,Ops!$L$2:'Ops'!$M$11,2,FALSE),"000")),2)} -> 00 | Z33: =IF(O33="", "};", "0x"&O33&",") -> 0x00, | AA33: ="0x"&P33&"," -> 0x00, | AB33: ="0x"&Q33&"," -> 0x00,
A34: =A33+3 -> 108 | B34: =DEC2HEX(A34) -> 6C | F34: 0 | O34: {=BIN2HEX(IF(I34<>"",VLOOKUP(I34,Ops!$I$2:'Ops'!$J$13,2,FALSE),IF(ISNUMBER(SEARCH("BR",D34)),"001","000"))&IF(D34<>"",VLOOKUP(D34,Ops!$B$2:'Ops'!$C$23,2,FALSE),"0")&_xlfn.IFS(ISNUMBER(SEARCH("BR",D34)),VLOOKUP(D34,Ops!$B$3:'Ops'!$D$22,3,FALSE),F34<>"",VLOOKUP(F34,Ops!$R$2:'Ops'!$S$11,2),L34<>"",VLOOKUP(L34,Ops!$R$2:'Ops'!$S$25,2,FALSE),TRUE,"0000"),2)} -> 00 | P34: =RIGHT(IF($E34<>"",_xlfn.XLOOKUP($E34,$C$4:$C$681,$B$4:$B$681,"NO LABEL"),BIN2HEX(IF(N34="CarryEn","1","0")&IF(M34="SubXY","1","0")&IF(H34<>"",VLOOKUP(H34,Ops!$F$2:'Ops'!$G$20,2,FALSE),"000000"),2)),2) -> 00 | Q34: {=BIN2HEX(_xlfn.IFS(D34="HWINTEN","10",G34="KeyAck","01",G34="InitLp8","01",TRUE,"00")&IF(OR(Ops!$O$2:'Ops'!$O$13=K34),VLOOKUP(K34,Ops!$O$2:'Ops'!$P$13,2,FALSE),"000")&IF(E34<>"",IF(LEN(_xlfn.XLOOKUP($E34,$C$5:$C$681,$B$5:$B$681,0))=3,HEX2BIN(LEFT(_xlfn.XLOOKUP($E34,$C$5:$C$681,$B$5:$B$681,0),1),3),IF(OR(Ops!$L$2:'Ops'!$L$11=J34),VLOOKUP(J34,Ops!$L$2:'Ops'!$M$11,2,FALSE),"000")),IF(OR(Ops!$L$2:'Ops'!$L$11=J34),VLOOKUP(J34,Ops!$L$2:'Ops'!$M$11,2,FALSE),"000")),2)} -> 00 | Z34: =IF(O34="", "};", "0x"&O34&",") -> 0x00, | AA34: ="0x"&P34&"," -> 0x00, | AB34: ="0x"&Q34&"," -> 0x00,
A35: =A34+3 -> 111 | B35: =DEC2HEX(A35) -> 6F | F35: 0 | H35: CircX | I35: SelXReg | J35: SelXXlsd | O35: {=BIN2HEX(IF(I35<>"",VLOOKUP(I35,Ops!$I$2:'Ops'!$J$13,2,FALSE),IF(ISNUMBER(SEARCH("BR",D35)),"001","000"))&IF(D35<>"",VLOOKUP(D35,Ops!$B$2:'Ops'!$C$23,2,FALSE),"0")&_xlfn.IFS(ISNUMBER(SEARCH("BR",D35)),VLOOKUP(D35,Ops!$B$3:'Ops'!$D$22,3,FALSE),F35<>"",VLOOKUP(F35,Ops!$R$2:'Ops'!$S$11,2),L35<>"",VLOOKUP(L35,Ops!$R$2:'Ops'!$S$25,2,FALSE),TRUE,"0000"),2)} -> 20 | P35: =RIGHT(IF($E35<>"",_xlfn.XLOOKUP($E35,$C$4:$C$681,$B$4:$B$681,"NO LABEL"),BIN2HEX(IF(N35="CarryEn","1","0")&IF(M35="SubXY","1","0")&IF(H35<>"",VLOOKUP(H35,Ops!$F$2:'Ops'!$G$20,2,FALSE),"000000"),2)),2) -> 01 | Q35: {=BIN2HEX(_xlfn.IFS(D35="HWINTEN","10",G35="KeyAck","01",G35="InitLp8","01",TRUE,"00")&IF(OR(Ops!$O$2:'Ops'!$O$13=K35),VLOOKUP(K35,Ops!$O$2:'Ops'!$P$13,2,FALSE),"000")&IF(E35<>"",IF(LEN(_xlfn.XLOOKUP($E35,$C$5:$C$681,$B$5:$B$681,0))=3,HEX2BIN(LEFT(_xlfn.XLOOKUP($E35,$C$5:$C$681,$B$5:$B$681,0),1),3),IF(OR(Ops!$L$2:'Ops'!$L$11=J35),VLOOKUP(J35,Ops!$L$2:'Ops'!$M$11,2,FALSE),"000")),IF(OR(Ops!$L$2:'Ops'!$L$11=J35),VLOOKUP(J35,Ops!$L$2:'Ops'!$M$11,2,FALSE),"000")),2)} -> 00 | S35: Rotate Xreg (XDig8<--XDig2; XDig1<--XDig1) | Z35: =IF(O35="", "};", "0x"&O35&",") -> 0x20, | AA35: ="0x"&P35&"," -> 0x01, | AB35: ="0x"&Q35&"," -> 0x00,
A36: =A35+3 -> 114 | B36: =DEC2HEX(A36) -> 72 | F36: 1 | O36: {=BIN2HEX(IF(I36<>"",VLOOKUP(I36,Ops!$I$2:'Ops'!$J$13,2,FALSE),IF(ISNUMBER(SEARCH("BR",D36)),"001","000"))&IF(D36<>"",VLOOKUP(D36,Ops!$B$2:'Ops'!$C$23,2,FALSE),"0")&_xlfn.IFS(ISNUMBER(SEARCH("BR",D36)),VLOOKUP(D36,Ops!$B$3:'Ops'!$D$22,3,FALSE),F36<>"",VLOOKUP(F36,Ops!$R$2:'Ops'!$S$11,2),L36<>"",VLOOKUP(L36,Ops!$R$2:'Ops'!$S$25,2,FALSE),TRUE,"0000"),2)} -> 01 | P36: =RIGHT(IF($E36<>"",_xlfn.XLOOKUP($E36,$C$4:$C$681,$B$4:$B$681,"NO LABEL"),BIN2HEX(IF(N36="CarryEn","1","0")&IF(M36="SubXY","1","0")&IF(H36<>"",VLOOKUP(H36,Ops!$F$2:'Ops'!$G$20,2,FALSE),"000000"),2)),2) -> 00 | Q36: {=BIN2HEX(_xlfn.IFS(D36="HWINTEN","10",G36="KeyAck","01",G36="InitLp8","01",TRUE,"00")&IF(OR(Ops!$O$2:'Ops'!$O$13=K36),VLOOKUP(K36,Ops!$O$2:'Ops'!$P$13,2,FALSE),"000")&IF(E36<>"",IF(LEN(_xlfn.XLOOKUP($E36,$C$5:$C$681,$B$5:$B$681,0))=3,HEX2BIN(LEFT(_xlfn.XLOOKUP($E36,$C$5:$C$681,$B$5:$B$681,0),1),3),IF(OR(Ops!$L$2:'Ops'!$L$11=J36),VLOOKUP(J36,Ops!$L$2:'Ops'!$M$11,2,FALSE),"000")),IF(OR(Ops!$L$2:'Ops'!$L$11=J36),VLOOKUP(J36,Ops!$L$2:'Ops'!$M$11,2,FALSE),"000")),2)} -> 00 | S36: Light up XDig2 | Z36: =IF(O36="", "};", "0x"&O36&",") -> 0x01, | AA36: ="0x"&P36&"," -> 0x00, | AB36: ="0x"&Q36&"," -> 0x00,
A37: =A36+3 -> 117 | B37: =DEC2HEX(A37) -> 75 | F37: 1 | O37: {=BIN2HEX(IF(I37<>"",VLOOKUP(I37,Ops!$I$2:'Ops'!$J$13,2,FALSE),IF(ISNUMBER(SEARCH("BR",D37)),"001","000"))&IF(D37<>"",VLOOKUP(D37,Ops!$B$2:'Ops'!$C$23,2,FALSE),"0")&_xlfn.IFS(ISNUMBER(SEARCH("BR",D37)),VLOOKUP(D37,Ops!$B$3:'Ops'!$D$22,3,FALSE),F37<>"",VLOOKUP(F37,Ops!$R$2:'Ops'!$S$11,2),L37<>"",VLOOKUP(L37,Ops!$R$2:'Ops'!$S$25,2,FALSE),TRUE,"0000"),2)} -> 01 | P37: =RIGHT(IF($E37<>"",_xlfn.XLOOKUP($E37,$C$4:$C$681,$B$4:$B$681,"NO LABEL"),BIN2HEX(IF(N37="CarryEn","1","0")&IF(M37="SubXY","1","0")&IF(H37<>"",VLOOKUP(H37,Ops!$F$2:'Ops'!$G$20,2,FALSE),"000000"),2)),2) -> 00 | Q37: {=BIN2HEX(_xlfn.IFS(D37="HWINTEN","10",G37="KeyAck","01",G37="InitLp8","01",TRUE,"00")&IF(OR(Ops!$O$2:'Ops'!$O$13=K37),VLOOKUP(K37,Ops!$O$2:'Ops'!$P$13,2,FALSE),"000")&IF(E37<>"",IF(LEN(_xlfn.XLOOKUP($E37,$C$5:$C$681,$B$5:$B$681,0))=3,HEX2BIN(LEFT(_xlfn.XLOOKUP($E37,$C$5:$C$681,$B$5:$B$681,0),1),3),IF(OR(Ops!$L$2:'Ops'!$L$11=J37),VLOOKUP(J37,Ops!$L$2:'Ops'!$M$11,2,FALSE),"000")),IF(OR(Ops!$L$2:'Ops'!$L$11=J37),VLOOKUP(J37,Ops!$L$2:'Ops'!$M$11,2,FALSE),"000")),2)} -> 00 | Z37: =IF(O37="", "};", "0x"&O37&",") -> 0x01, | AA37: ="0x"&P37&"," -> 0x00, | AB37: ="0x"&Q37&"," -> 0x00,
A38: =A37+3 -> 120 | B38: =DEC2HEX(A38) -> 78 | F38: 1 | O38: {=BIN2HEX(IF(I38<>"",VLOOKUP(I38,Ops!$I$2:'Ops'!$J$13,2,FALSE),IF(ISNUMBER(SEARCH("BR",D38)),"001","000"))&IF(D38<>"",VLOOKUP(D38,Ops!$B$2:'Ops'!$C$23,2,FALSE),"0")&_xlfn.IFS(ISNUMBER(SEARCH("BR",D38)),VLOOKUP(D38,Ops!$B$3:'Ops'!$D$22,3,FALSE),F38<>"",VLOOKUP(F38,Ops!$R$2:'Ops'!$S$11,2),L38<>"",VLOOKUP(L38,Ops!$R$2:'Ops'!$S$25,2,FALSE),TRUE,"0000"),2)} -> 01 | P38: =RIGHT(IF($E38<>"",_xlfn.XLOOKUP($E38,$C$4:$C$681,$B$4:$B$681,"NO LABEL"),BIN2HEX(IF(N38="CarryEn","1","0")&IF(M38="SubXY","1","0")&IF(H38<>"",VLOOKUP(H38,Ops!$F$2:'Ops'!$G$20,2,FALSE),"000000"),2)),2) -> 00 | Q38: {=BIN2HEX(_xlfn.IFS(D38="HWINTEN","10",G38="KeyAck","01",G38="InitLp8","01",TRUE,"00")&IF(OR(Ops!$O$2:'Ops'!$O$13=K38),VLOOKUP(K38,Ops!$O$2:'Ops'!$P$13,2,FALSE),"000")&IF(E38<>"",IF(LEN(_xlfn.XLOOKUP($E38,$C$5:$C$681,$B$5:$B$681,0))=3,HEX2BIN(LEFT(_xlfn.XLOOKUP($E38,$C$5:$C$681,$B$5:$B$681,0),1),3),IF(OR(Ops!$L$2:'Ops'!$L$11=J38),VLOOKUP(J38,Ops!$L$2:'Ops'!$M$11,2,FALSE),"000")),IF(OR(Ops!$L$2:'Ops'!$L$11=J38),VLOOKUP(J38,Ops!$L$2:'Ops'!$M$11,2,FALSE),"000")),2)} -> 00 | Z38: =IF(O38="", "};", "0x"&O38&",") -> 0x01, | AA38: ="0x"&P38&"," -> 0x00, | AB38: ="0x"&Q38&"," -> 0x00,
A39: =A38+3 -> 123 | B39: =DEC2HEX(A39) -> 7B | F39: 1 | O39: {=BIN2HEX(IF(I39<>"",VLOOKUP(I39,Ops!$I$2:'Ops'!$J$13,2,FALSE),IF(ISNUMBER(SEARCH("BR",D39)),"001","000"))&IF(D39<>"",VLOOKUP(D39,Ops!$B$2:'Ops'!$C$23,2,FALSE),"0")&_xlfn.IFS(ISNUMBER(SEARCH("BR",D39)),VLOOKUP(D39,Ops!$B$3:'Ops'!$D$22,3,FALSE),F39<>"",VLOOKUP(F39,Ops!$R$2:'Ops'!$S$11,2),L39<>"",VLOOKUP(L39,Ops!$R$2:'Ops'!$S$25,2,FALSE),TRUE,"0000"),2)} -> 01 | P39: =RIGHT(IF($E39<>"",_xlfn.XLOOKUP($E39,$C$4:$C$681,$B$4:$B$681,"NO LABEL"),BIN2HEX(IF(N39="CarryEn","1","0")&IF(M39="SubXY","1","0")&IF(H39<>"",VLOOKUP(H39,Ops!$F$2:'Ops'!$G$20,2,FALSE),"000000"),2)),2) -> 00 | Q39: {=BIN2HEX(_xlfn.IFS(D39="HWINTEN","10",G39="KeyAck","01",G39="InitLp8","01",TRUE,"00")&IF(OR(Ops!$O$2:'Ops'!$O$13=K39),VLOOKUP(K39,Ops!$O$2:'Ops'!$P$13,2,FALSE),"000")&IF(E39<>"",IF(LEN(_xlfn.XLOOKUP($E39,$C$5:$C$681,$B$5:$B$681,0))=3,HEX2BIN(LEFT(_xlfn.XLOOKUP($E39,$C$5:$C$681,$B$5:$B$681,0),1),3),IF(OR(Ops!$L$2:'Ops'!$L$11=J39),VLOOKUP(J39,Ops!$L$2:'Ops'!$M$11,2,FALSE),"000")),IF(OR(Ops!$L$2:'Ops'!$L$11=J39),VLOOKUP(J39,Ops!$L$2:'Ops'!$M$11,2,FALSE),"000")),2)} -> 00 | Z39: =IF(O39="", "};", "0x"&O39&",") -> 0x01, | AA39: ="0x"&P39&"," -> 0x00, | AB39: ="0x"&Q39&"," -> 0x00,
A40: =A39+3 -> 126 | B40: =DEC2HEX(A40) -> 7E | F40: 1 | H40: CircX | I40: SelXReg | J40: SelXXlsd | O40: {=BIN2HEX(IF(I40<>"",VLOOKUP(I40,Ops!$I$2:'Ops'!$J$13,2,FALSE),IF(ISNUMBER(SEARCH("BR",D40)),"001","000"))&IF(D40<>"",VLOOKUP(D40,Ops!$B$2:'Ops'!$C$23,2,FALSE),"0")&_xlfn.IFS(ISNUMBER(SEARCH("BR",D40)),VLOOKUP(D40,Ops!$B$3:'Ops'!$D$22,3,FALSE),F40<>"",VLOOKUP(F40,Ops!$R$2:'Ops'!$S$11,2),L40<>"",VLOOKUP(L40,Ops!$R$2:'Ops'!$S$25,2,FALSE),TRUE,"0000"),2)} -> 21 | P40: =RIGHT(IF($E40<>"",_xlfn.XLOOKUP($E40,$C$4:$C$681,$B$4:$B$681,"NO LABEL"),BIN2HEX(IF(N40="CarryEn","1","0")&IF(M40="SubXY","1","0")&IF(H40<>"",VLOOKUP(H40,Ops!$F$2:'Ops'!$G$20,2,FALSE),"000000"),2)),2) -> 01 | Q40: {=BIN2HEX(_xlfn.IFS(D40="HWINTEN","10",G40="KeyAck","01",G40="InitLp8","01",TRUE,"00")&IF(OR(Ops!$O$2:'Ops'!$O$13=K40),VLOOKUP(K40,Ops!$O$2:'Ops'!$P$13,2,FALSE),"000")&IF(E40<>"",IF(LEN(_xlfn.XLOOKUP($E40,$C$5:$C$681,$B$5:$B$681,0))=3,HEX2BIN(LEFT(_xlfn.XLOOKUP($E40,$C$5:$C$681,$B$5:$B$681,0),1),3),IF(OR(Ops!$L$2:'Ops'!$L$11=J40),VLOOKUP(J40,Ops!$L$2:'Ops'!$M$11,2,FALSE),"000")),IF(OR(Ops!$L$2:'Ops'!$L$11=J40),VLOOKUP(J40,Ops!$L$2:'Ops'!$M$11,2,FALSE),"000")),2)} -> 00 | Z40: =IF(O40="", "};", "0x"&O40&",") -> 0x21, | AA40: ="0x"&P40&"," -> 0x01, | AB40: ="0x"&Q40&"," -> 0x00,
A41: =A40+3 -> 129 | B41: =DEC2HEX(A41) -> 81 | F41: 2 | O41: {=BIN2HEX(IF(I41<>"",VLOOKUP(I41,Ops!$I$2:'Ops'!$J$13,2,FALSE),IF(ISNUMBER(SEARCH("BR",D41)),"001","000"))&IF(D41<>"",VLOOKUP(D41,Ops!$B$2:'Ops'!$C$23,2,FALSE),"0")&_xlfn.IFS(ISNUMBER(SEARCH("BR",D41)),VLOOKUP(D41,Ops!$B$3:'Ops'!$D$22,3,FALSE),F41<>"",VLOOKUP(F41,Ops!$R$2:'Ops'!$S$11,2),L41<>"",VLOOKUP(L41,Ops!$R$2:'Ops'!$S$25,2,FALSE),TRUE,"0000"),2)} -> 02 | P41: =RIGHT(IF($E41<>"",_xlfn.XLOOKUP($E41,$C$4:$C$681,$B$4:$B$681,"NO LABEL"),BIN2HEX(IF(N41="CarryEn","1","0")&IF(M41="SubXY","1","0")&IF(H41<>"",VLOOKUP(H41,Ops!$F$2:'Ops'!$G$20,2,FALSE),"000000"),2)),2) -> 00 | Q41: {=BIN2HEX(_xlfn.IFS(D41="HWINTEN","10",G41="KeyAck","01",G41="InitLp8","01",TRUE,"00")&IF(OR(Ops!$O$2:'Ops'!$O$13=K41),VLOOKUP(K41,Ops!$O$2:'Ops'!$P$13,2,FALSE),"000")&IF(E41<>"",IF(LEN(_xlfn.XLOOKUP($E41,$C$5:$C$681,$B$5:$B$681,0))=3,HEX2BIN(LEFT(_xlfn.XLOOKUP($E41,$C$5:$C$681,$B$5:$B$681,0),1),3),IF(OR(Ops!$L$2:'Ops'!$L$11=J41),VLOOKUP(J41,Ops!$L$2:'Ops'!$M$11,2,FALSE),"000")),IF(OR(Ops!$L$2:'Ops'!$L$11=J41),VLOOKUP(J41,Ops!$L$2:'Ops'!$M$11,2,FALSE),"000")),2)} -> 00 | Z41: =IF(O41="", "};", "0x"&O41&",") -> 0x02, | AA41: ="0x"&P41&"," -> 0x00, | AB41: ="0x"&Q41&"," -> 0x00,
A42: =A41+3 -> 132 | B42: =DEC2HEX(A42) -> 84 | F42: 2 | O42: {=BIN2HEX(IF(I42<>"",VLOOKUP(I42,Ops!$I$2:'Ops'!$J$13,2,FALSE),IF(ISNUMBER(SEARCH("BR",D42)),"001","000"))&IF(D42<>"",VLOOKUP(D42,Ops!$B$2:'Ops'!$C$23,2,FALSE),"0")&_xlfn.IFS(ISNUMBER(SEARCH("BR",D42)),VLOOKUP(D42,Ops!$B$3:'Ops'!$D$22,3,FALSE),F42<>"",VLOOKUP(F42,Ops!$R$2:'Ops'!$S$11,2),L42<>"",VLOOKUP(L42,Ops!$R$2:'Ops'!$S$25,2,FALSE),TRUE,"0000"),2)} -> 02 | P42: =RIGHT(IF($E42<>"",_xlfn.XLOOKUP($E42,$C$4:$C$681,$B$4:$B$681,"NO LABEL"),BIN2HEX(IF(N42="CarryEn","1","0")&IF(M42="SubXY","1","0")&IF(H42<>"",VLOOKUP(H42,Ops!$F$2:'Ops'!$G$20,2,FALSE),"000000"),2)),2) -> 00 | Q42: {=BIN2HEX(_xlfn.IFS(D42="HWINTEN","10",G42="KeyAck","01",G42="InitLp8","01",TRUE,"00")&IF(OR(Ops!$O$2:'Ops'!$O$13=K42),VLOOKUP(K42,Ops!$O$2:'Ops'!$P$13,2,FALSE),"000")&IF(E42<>"",IF(LEN(_xlfn.XLOOKUP($E42,$C$5:$C$681,$B$5:$B$681,0))=3,HEX2BIN(LEFT(_xlfn.XLOOKUP($E42,$C$5:$C$681,$B$5:$B$681,0),1),3),IF(OR(Ops!$L$2:'Ops'!$L$11=J42),VLOOKUP(J42,Ops!$L$2:'Ops'!$M$11,2,FALSE),"000")),IF(OR(Ops!$L$2:'Ops'!$L$11=J42),VLOOKUP(J42,Ops!$L$2:'Ops'!$M$11,2,FALSE),"000")),2)} -> 00 | Z42: =IF(O42="", "};", "0x"&O42&",") -> 0x02, | AA42: ="0x"&P42&"," -> 0x00, | AB42: ="0x"&Q42&"," -> 0x00,
A43: =A42+3 -> 135 | B43: =DEC2HEX(A43) -> 87 | F43: 2 | O43: {=BIN2HEX(IF(I43<>"",VLOOKUP(I43,Ops!$I$2:'Ops'!$J$13,2,FALSE),IF(ISNUMBER(SEARCH("BR",D43)),"001","000"))&IF(D43<>"",VLOOKUP(D43,Ops!$B$2:'Ops'!$C$23,2,FALSE),"0")&_xlfn.IFS(ISNUMBER(SEARCH("BR",D43)),VLOOKUP(D43,Ops!$B$3:'Ops'!$D$22,3,FALSE),F43<>"",VLOOKUP(F43,Ops!$R$2:'Ops'!$S$11,2),L43<>"",VLOOKUP(L43,Ops!$R$2:'Ops'!$S$25,2,FALSE),TRUE,"0000"),2)} -> 02 | P43: =RIGHT(IF($E43<>"",_xlfn.XLOOKUP($E43,$C$4:$C$681,$B$4:$B$681,"NO LABEL"),BIN2HEX(IF(N43="CarryEn","1","0")&IF(M43="SubXY","1","0")&IF(H43<>"",VLOOKUP(H43,Ops!$F$2:'Ops'!$G$20,2,FALSE),"000000"),2)),2) -> 00 | Q43: {=BIN2HEX(_xlfn.IFS(D43="HWINTEN","10",G43="KeyAck","01",G43="InitLp8","01",TRUE,"00")&IF(OR(Ops!$O$2:'Ops'!$O$13=K43),VLOOKUP(K43,Ops!$O$2:'Ops'!$P$13,2,FALSE),"000")&IF(E43<>"",IF(LEN(_xlfn.XLOOKUP($E43,$C$5:$C$681,$B$5:$B$681,0))=3,HEX2BIN(LEFT(_xlfn.XLOOKUP($E43,$C$5:$C$681,$B$5:$B$681,0),1),3),IF(OR(Ops!$L$2:'Ops'!$L$11=J43),VLOOKUP(J43,Ops!$L$2:'Ops'!$M$11,2,FALSE),"000")),IF(OR(Ops!$L$2:'Ops'!$L$11=J43),VLOOKUP(J43,Ops!$L$2:'Ops'!$M$11,2,FALSE),"000")),2)} -> 00 | Z43: =IF(O43="", "};", "0x"&O43&",") -> 0x02, | AA43: ="0x"&P43&"," -> 0x00, | AB43: ="0x"&Q43&"," -> 0x00,
...
